<?xml version="1.0" ?>
<!-- =================================================================================== -->
<!-- |    This document was autogenerated by xacro from wam7.urdf.xacro                | -->
<!-- |    EDITING THIS FILE BY HAND IS NOT RECOMMENDED                                 | -->
<!-- =================================================================================== -->
<robot name="wam" xmlns:xacro="http://www.ros.org/wiki/xacro">

    <!-- Materials -->
    <material name="WAMGrey">
        <color rgba="0.7 0.7 0.7 1.0"/>
    </material>

    <!-- Root link is in the world frame-->
    <link name="world"/>
    <joint name="wam_fixed_joint" type="fixed">
        <parent link="world"/>
        <child link="base_link"/>
        <origin rpy="0 0 1.5707" xyz="0.0 0.0 0.0"/>
    </joint>

    <link name="base_link">
        <inertial>
            <origin rpy="1.57 0 0" xyz="0.0 0.0 0.84"/>
            <mass value="1"/>
            <inertia ixx="0.1" ixy="0" ixz="0" iyy="0.1" iyz="0" izz="0.1"/>
        </inertial>
        <visual>
            <material name="WAMGrey">
                <color rgba="0.7 0.7 0.7 0.0"/>
            </material>
            <geometry>
                <mesh filename="sw_meshes/base_link_fine.obj"/>
            </geometry>
        </visual>
        <collision>
            <geometry>
                <mesh filename="sw_meshes/base_link_convex.obj"/>
            </geometry>
        </collision>
    </link>
    <joint name="R_SFE" type="revolute">
        <parent link="base_link"/>
        <child link="shoulder_yaw_link"/>
        <origin rpy="0 0 -1.57079632679" xyz="0 0 0.346"/>
        <axis xyz="0 0 1"/>
        <limit effort="60" lower="-2.6" upper="2.6" velocity="2.0"/>
        <dynamics damping="0.9" friction="0"/>
    </joint>

    <link name="shoulder_yaw_link">
        <inertial>
            <origin xyz="-.00443422 -.00066489 -0.1289039 "/>
            <mass value="5.0"/>
            <inertia ixx=".13488033" ixy="-0.00012485" ixz="0.00213041" iyy=".09046330" iyz="-.00068555"
                     izz=".11328369"/>
        </inertial>
        <visual>
            <material name="WAMGrey">
                <color rgba="0.7 0.7 0.7 1.0"/>
            </material>
            <geometry>
                <mesh filename="sw_meshes/shoulder_link_fine.obj"/>
            </geometry>
        </visual>
        <collision>
            <geometry>
                <mesh filename="sw_meshes/shoulder_link_convex_decomposition.obj"/>
            </geometry>
        </collision>
    </link>

    <joint name="R_SAA" type="revolute">
        <parent link="shoulder_yaw_link"/>
        <child link="shoulder_pitch_link"/>
        <origin rpy="-1.57079632679 0 0" xyz="0 0 0"/>
        <axis xyz="0 0 1"/>
        <limit effort="60" lower="-2.1" upper="2.0" velocity="2.0"/>
        <dynamics damping="0.25" friction="0"/>
    </joint>

    <link name="shoulder_pitch_link">
        <visual>
            <material name="WAMGrey">
                <color rgba="0.7 0.7 0.7 1.0"/>
            </material>
            <geometry>
                <mesh filename="sw_meshes/shoulder_pitch_link_fine.obj"/>
            </geometry>
        </visual>
        <inertial>
            <origin xyz="-.00236981 -.01542114 .03105614 "/>
            <mass value="3.87493756"/>
            <inertia ixx="0.02140958" ixy="-0.00002461" ixz="0.00027172" iyy="0.015589060" iyz="0.0018192"
                     izz="0.01377875"/>
        </inertial>
        <collision>
            <geometry>
                <mesh filename="sw_meshes/shoulder_pitch_link_convex.obj"/>
            </geometry>
        </collision>
    </link>

    <joint name="R_HR" type="revolute">
        <parent link="shoulder_pitch_link"/>
        <child link="upper_arm_link"/>
        <origin rpy="1.57079632679 0 0" xyz="0 0 0"/>
        <axis xyz="0 0 1"/>
        <limit effort="45" lower="-2.8" upper="2.8" velocity="2.0"/>
        <dynamics damping="0.75" friction="0"/>
    </joint>

    <link name="upper_arm_link">
        <inertial>
            <origin xyz="0.00683258580000000 0.000033090000000 0.392492300000000"/>
            <mass value="2.20228141"/>
            <inertia ixx=".05911077" ixy="-0.00000738" ixz="-0.00249612" iyy="0.05927043" iyz="0.00001767"
                     izz="0.0032455"/>
        </inertial>
        <visual>
            <material name="WAMGrey">
                <color rgba="0.7 0.7 0.7 1.0"/>
            </material>
            <geometry>
                <mesh filename="sw_meshes/upper_arm_link_fine.obj"/>
            </geometry>
        </visual>
        <collision>
            <geometry>
                <mesh filename="sw_meshes/upper_arm_link_convex_decomposition.obj"/>
            </geometry>
        </collision>
    </link>

    <joint name="R_EB" type="revolute">
        <parent link="upper_arm_link"/>
        <child link="forearm_link"/>
        <origin rpy="-1.57079632679 0 0" xyz="0.045 0 0.55"/>
        <axis xyz="0 0 1"/>
        <limit effort="30" lower="-0.9" upper="3.2" velocity="2.00"/>
        <dynamics damping="0.4" friction="0"/>
    </joint>

    <link name="forearm_link">
        <inertial>
            <mass value="1.06513649"/>
            <origin rpy="1.5707 0 0" xyz="0.01095471 0.14053900 -0.00002567"/>
            <inertia ixx="0.03952350" ixy="0.00000189" ixz="0.00003117" iyy="0.04008214" iyz="0.00000131"
                     izz="0.00210299"/>
        </inertial>
        <visual>
            <origin rpy="0 0 0" xyz="0 0 0"/>
            <geometry name="link_j4_visual">
                <mesh filename="sw_meshes/wam4.obj"/>
            </geometry>
        </visual>
        <collision>
            <origin rpy="1.5707 0 0" xyz="0 0 0"/>
            <geometry name="link_j4_collision">
                <mesh filename="sw_meshes/wam4.obj"/>
            </geometry>
            <contact_coefficients kd="1000.0" kp="1000.0" mu="0"/>
        </collision>
    </link>

    <joint name="FOREARM_TO_CUP" type="fixed">
        <parent link="forearm_link"/>
        <child link="cup"/>
        <origin xyz="-0.1 -0.3225 0.0"/>
    </joint>

    <link name="cup">
        <inertial>
            <mass value="0.132"/>
            <origin xyz="-3.75236e-10 8.27811e-05 0.0947015" rpy="0.0 -0.0199993 0.0"/>
            <inertia ixx="0.000285643" ixy="0.0" ixz="0.0" iyy="0.000270485" iyz="0.0" izz="9.65696e-05"/>
        </inertial>
        <visual>
            <origin rpy="1.5707 -1.5707 0" xyz="0. 0. 0."/>
            <material name="WAMGrey">
                <color rgba="0.7 0.7 0.7 1.0"/>
            </material>
            <geometry name="cup_visual">
                <mesh filename="sw_meshes/cup.obj" scale="0.001 0.001 0.001"/>
            </geometry>
        </visual>
        <collision>
            <origin rpy="1.5707 -1.5707 0" xyz="0 0 0"/>
            <geometry name="cup_collision">
                <mesh filename="sw_meshes/cup.obj" scale="0.001 0.001 0.001"/>
            </geometry>
        </collision>
    </link>

    <joint name="attach" type="fixed">
        <origin xyz="0.09 -0.06 0.0" rpy="0 -1.5707 0"/>
        <parent link="cup"/>
        <child link="R0"/>
    </joint>

    <link name="R0">
        <inertial>
            <mass value="0.0003"/>
            <origin xyz="0. 0. -8.600E-03" rpy="0. 0. 0."/>
            <inertia ixx="7.471E-09" ixy="0.0" ixz="0.0" iyy="7.471E-09" iyz="0.0" izz="1.500E-10"/>
        </inertial>
        <visual>
            <material name="WAMGrey">
                <color rgba="0.7 0.7 0.7 1.0"/>
            </material>
            <origin xyz="0.0 0.0 -8.600E-03"/>
            <geometry>
                <cylinder radius="0.001" length="0.0172"/>
            </geometry>
        </visual>
        <collision>
            <origin xyz="0.0 0.0 -8.600E-03"/>
            <geometry>
                <cylinder radius="0.001" length="0.0172"/>
            </geometry>
        </collision>
    </link>
    <joint name="R0_1_FIX" type="continuous">
        <origin xyz="0. 0.0 -8.600E-03" rpy="0 0 0"/>
        <axis xyz="1 0 0"/>
        <parent link="R0"/>
        <child link="R0_FIX"/>
    </joint>
    <link name="R0_FIX"/>
    <joint name="R0_1" type="continuous">
        <origin xyz="0. 0.0 0." rpy="0 0 0"/>
        <axis xyz="0 1 0"/>
        <parent link="R0_FIX"/>
        <child link="R1"/>
    </joint>
    <link name="R1">
        <inertial>
            <mass value="0.0003"/>
            <origin xyz="0. 0. -8.600E-03" rpy="0. 0. 0."/>
            <inertia ixx="7.471E-09" ixy="0.0" ixz="0.0" iyy="7.471E-09" iyz="0.0" izz="1.500E-10"/>
        </inertial>
        <visual>
            <material name="WAMGrey">
                <color rgba="0.7 0.7 0.7 1.0"/>
            </material>
            <origin xyz="0.0 0.0 -8.600E-03"/>
            <geometry>
                <cylinder radius="0.001" length="0.0172"/>
            </geometry>
        </visual>
        <collision>
            <origin xyz="0.0 0.0 -8.600E-03"/>
            <geometry>
                <cylinder radius="0.001" length="0.0172"/>
            </geometry>
        </collision>
    </link>
    <joint name="R1_2_FIX" type="continuous">
        <origin xyz="0. 0.0 -8.600E-03" rpy="0 0 0"/>
        <axis xyz="1 0 0"/>
        <parent link="R1"/>
        <child link="R1_FIX"/>
    </joint>
    <link name="R1_FIX"/>
    <joint name="R1_2" type="continuous">
        <origin xyz="0. 0.0 0." rpy="0 0 0"/>
        <axis xyz="0 1 0"/>
        <parent link="R1_FIX"/>
        <child link="R2"/>
    </joint>
    <link name="R2">
        <inertial>
            <mass value="0.0003"/>
            <origin xyz="0. 0. -8.600E-03" rpy="0. 0. 0."/>
            <inertia ixx="7.471E-09" ixy="0.0" ixz="0.0" iyy="7.471E-09" iyz="0.0" izz="1.500E-10"/>
        </inertial>
        <visual>
            <material name="WAMGrey">
                <color rgba="0.7 0.7 0.7 1.0"/>
            </material>
            <origin xyz="0.0 0.0 -8.600E-03"/>
            <geometry>
                <cylinder radius="0.001" length="0.0172"/>
            </geometry>
        </visual>
        <collision>
            <origin xyz="0.0 0.0 -8.600E-03"/>
            <geometry>
                <cylinder radius="0.001" length="0.0172"/>
            </geometry>
        </collision>
    </link>
    <joint name="R2_3_FIX" type="continuous">
        <origin xyz="0. 0.0 -8.600E-03" rpy="0 0 0"/>
        <axis xyz="1 0 0"/>
        <parent link="R2"/>
        <child link="R2_FIX"/>
    </joint>
    <link name="R2_FIX"/>
    <joint name="R2_3" type="continuous">
        <origin xyz="0. 0.0 0." rpy="0 0 0"/>
        <axis xyz="0 1 0"/>
        <parent link="R2_FIX"/>
        <child link="R3"/>
    </joint>
    <link name="R3">
        <inertial>
            <mass value="0.0003"/>
            <origin xyz="0. 0. -8.600E-03" rpy="0. 0. 0."/>
            <inertia ixx="7.471E-09" ixy="0.0" ixz="0.0" iyy="7.471E-09" iyz="0.0" izz="1.500E-10"/>
        </inertial>
        <visual>
            <material name="WAMGrey">
                <color rgba="0.7 0.7 0.7 1.0"/>
            </material>
            <origin xyz="0.0 0.0 -8.600E-03"/>
            <geometry>
                <cylinder radius="0.001" length="0.0172"/>
            </geometry>
        </visual>
        <collision>
            <origin xyz="0.0 0.0 -8.600E-03"/>
            <geometry>
                <cylinder radius="0.001" length="0.0172"/>
            </geometry>
        </collision>
    </link>
    <joint name="R3_4_FIX" type="continuous">
        <origin xyz="0. 0.0 -8.600E-03" rpy="0 0 0"/>
        <axis xyz="1 0 0"/>
        <parent link="R3"/>
        <child link="R3_FIX"/>
    </joint>
    <link name="R3_FIX"/>
    <joint name="R3_4" type="continuous">
        <origin xyz="0. 0.0 0." rpy="0 0 0"/>
        <axis xyz="0 1 0"/>
        <parent link="R3_FIX"/>
        <child link="R4"/>
    </joint>
    <link name="R4">
        <inertial>
            <mass value="0.0003"/>
            <origin xyz="0. 0. -8.600E-03" rpy="0. 0. 0."/>
            <inertia ixx="7.471E-09" ixy="0.0" ixz="0.0" iyy="7.471E-09" iyz="0.0" izz="1.500E-10"/>
        </inertial>
        <visual>
            <material name="WAMGrey">
                <color rgba="0.7 0.7 0.7 1.0"/>
            </material>
            <origin xyz="0.0 0.0 -8.600E-03"/>
            <geometry>
                <cylinder radius="0.001" length="0.0172"/>
            </geometry>
        </visual>
        <collision>
            <origin xyz="0.0 0.0 -8.600E-03"/>
            <geometry>
                <cylinder radius="0.001" length="0.0172"/>
            </geometry>
        </collision>
    </link>
    <joint name="R4_5_FIX" type="continuous">
        <origin xyz="0. 0.0 -8.600E-03" rpy="0 0 0"/>
        <axis xyz="1 0 0"/>
        <parent link="R4"/>
        <child link="R4_FIX"/>
    </joint>
    <link name="R4_FIX"/>
    <joint name="R4_5" type="continuous">
        <origin xyz="0. 0.0 0." rpy="0 0 0"/>
        <axis xyz="0 1 0"/>
        <parent link="R4_FIX"/>
        <child link="R5"/>
    </joint>
    <link name="R5">
        <inertial>
            <mass value="0.0003"/>
            <origin xyz="0. 0. -8.600E-03" rpy="0. 0. 0."/>
            <inertia ixx="7.471E-09" ixy="0.0" ixz="0.0" iyy="7.471E-09" iyz="0.0" izz="1.500E-10"/>
        </inertial>
        <visual>
            <material name="WAMGrey">
                <color rgba="0.7 0.7 0.7 1.0"/>
            </material>
            <origin xyz="0.0 0.0 -8.600E-03"/>
            <geometry>
                <cylinder radius="0.001" length="0.0172"/>
            </geometry>
        </visual>
        <collision>
            <origin xyz="0.0 0.0 -8.600E-03"/>
            <geometry>
                <cylinder radius="0.001" length="0.0172"/>
            </geometry>
        </collision>
    </link>
    <joint name="R5_6_FIX" type="continuous">
        <origin xyz="0. 0.0 -8.600E-03" rpy="0 0 0"/>
        <axis xyz="1 0 0"/>
        <parent link="R5"/>
        <child link="R5_FIX"/>
    </joint>
    <link name="R5_FIX"/>
    <joint name="R5_6" type="continuous">
        <origin xyz="0. 0.0 0." rpy="0 0 0"/>
        <axis xyz="0 1 0"/>
        <parent link="R5_FIX"/>
        <child link="R6"/>
    </joint>
    <link name="R6">
        <inertial>
            <mass value="0.0003"/>
            <origin xyz="0. 0. -8.600E-03" rpy="0. 0. 0."/>
            <inertia ixx="7.471E-09" ixy="0.0" ixz="0.0" iyy="7.471E-09" iyz="0.0" izz="1.500E-10"/>
        </inertial>
        <visual>
            <material name="WAMGrey">
                <color rgba="0.7 0.7 0.7 1.0"/>
            </material>
            <origin xyz="0.0 0.0 -8.600E-03"/>
            <geometry>
                <cylinder radius="0.001" length="0.0172"/>
            </geometry>
        </visual>
        <collision>
            <origin xyz="0.0 0.0 -8.600E-03"/>
            <geometry>
                <cylinder radius="0.001" length="0.0172"/>
            </geometry>
        </collision>
    </link>
    <joint name="R6_7_FIX" type="continuous">
        <origin xyz="0. 0.0 -8.600E-03" rpy="0 0 0"/>
        <axis xyz="1 0 0"/>
        <parent link="R6"/>
        <child link="R6_FIX"/>
    </joint>
    <link name="R6_FIX"/>
    <joint name="R6_7" type="continuous">
        <origin xyz="0. 0.0 0." rpy="0 0 0"/>
        <axis xyz="0 1 0"/>
        <parent link="R6_FIX"/>
        <child link="R7"/>
    </joint>
    <link name="R7">
        <inertial>
            <mass value="0.0003"/>
            <origin xyz="0. 0. -8.600E-03" rpy="0. 0. 0."/>
            <inertia ixx="7.471E-09" ixy="0.0" ixz="0.0" iyy="7.471E-09" iyz="0.0" izz="1.500E-10"/>
        </inertial>
        <visual>
            <material name="WAMGrey">
                <color rgba="0.7 0.7 0.7 1.0"/>
            </material>
            <origin xyz="0.0 0.0 -8.600E-03"/>
            <geometry>
                <cylinder radius="0.001" length="0.0172"/>
            </geometry>
        </visual>
        <collision>
            <origin xyz="0.0 0.0 -8.600E-03"/>
            <geometry>
                <cylinder radius="0.001" length="0.0172"/>
            </geometry>
        </collision>
    </link>
    <joint name="R7_8_FIX" type="continuous">
        <origin xyz="0. 0.0 -8.600E-03" rpy="0 0 0"/>
        <axis xyz="1 0 0"/>
        <parent link="R7"/>
        <child link="R7_FIX"/>
    </joint>
    <link name="R7_FIX"/>
    <joint name="R7_8" type="continuous">
        <origin xyz="0. 0.0 0." rpy="0 0 0"/>
        <axis xyz="0 1 0"/>
        <parent link="R7_FIX"/>
        <child link="R8"/>
    </joint>
    <link name="R8">
        <inertial>
            <mass value="0.0003"/>
            <origin xyz="0. 0. -8.600E-03" rpy="0. 0. 0."/>
            <inertia ixx="7.471E-09" ixy="0.0" ixz="0.0" iyy="7.471E-09" iyz="0.0" izz="1.500E-10"/>
        </inertial>
        <visual>
            <material name="WAMGrey">
                <color rgba="0.7 0.7 0.7 1.0"/>
            </material>
            <origin xyz="0.0 0.0 -8.600E-03"/>
            <geometry>
                <cylinder radius="0.001" length="0.0172"/>
            </geometry>
        </visual>
        <collision>
            <origin xyz="0.0 0.0 -8.600E-03"/>
            <geometry>
                <cylinder radius="0.001" length="0.0172"/>
            </geometry>
        </collision>
    </link>
    <joint name="R8_9_FIX" type="continuous">
        <origin xyz="0. 0.0 -8.600E-03" rpy="0 0 0"/>
        <axis xyz="1 0 0"/>
        <parent link="R8"/>
        <child link="R8_FIX"/>
    </joint>
    <link name="R8_FIX"/>
    <joint name="R8_9" type="continuous">
        <origin xyz="0. 0.0 0." rpy="0 0 0"/>
        <axis xyz="0 1 0"/>
        <parent link="R8_FIX"/>
        <child link="R9"/>
    </joint>
    <link name="R9">
        <inertial>
            <mass value="0.0003"/>
            <origin xyz="0. 0. -8.600E-03" rpy="0. 0. 0."/>
            <inertia ixx="7.471E-09" ixy="0.0" ixz="0.0" iyy="7.471E-09" iyz="0.0" izz="1.500E-10"/>
        </inertial>
        <visual>
            <material name="WAMGrey">
                <color rgba="0.7 0.7 0.7 1.0"/>
            </material>
            <origin xyz="0.0 0.0 -8.600E-03"/>
            <geometry>
                <cylinder radius="0.001" length="0.0172"/>
            </geometry>
        </visual>
        <collision>
            <origin xyz="0.0 0.0 -8.600E-03"/>
            <geometry>
                <cylinder radius="0.001" length="0.0172"/>
            </geometry>
        </collision>
    </link>
    <joint name="R9_10_FIX" type="continuous">
        <origin xyz="0. 0.0 -8.600E-03" rpy="0 0 0"/>
        <axis xyz="1 0 0"/>
        <parent link="R9"/>
        <child link="R9_FIX"/>
    </joint>
    <link name="R9_FIX"/>
    <joint name="R9_10" type="continuous">
        <origin xyz="0. 0.0 0." rpy="0 0 0"/>
        <axis xyz="0 1 0"/>
        <parent link="R9_FIX"/>
        <child link="R10"/>
    </joint>
    <link name="R10">
        <inertial>
            <mass value="0.0003"/>
            <origin xyz="0. 0. -8.600E-03" rpy="0. 0. 0."/>
            <inertia ixx="7.471E-09" ixy="0.0" ixz="0.0" iyy="7.471E-09" iyz="0.0" izz="1.500E-10"/>
        </inertial>
        <visual>
            <material name="WAMGrey">
                <color rgba="0.7 0.7 0.7 1.0"/>
            </material>
            <origin xyz="0.0 0.0 -8.600E-03"/>
            <geometry>
                <cylinder radius="0.001" length="0.0172"/>
            </geometry>
        </visual>
        <collision>
            <origin xyz="0.0 0.0 -8.600E-03"/>
            <geometry>
                <cylinder radius="0.001" length="0.0172"/>
            </geometry>
        </collision>
    </link>
    <joint name="R10_11_FIX" type="continuous">
        <origin xyz="0. 0.0 -8.600E-03" rpy="0 0 0"/>
        <axis xyz="1 0 0"/>
        <parent link="R10"/>
        <child link="R10_FIX"/>
    </joint>
    <link name="R10_FIX"/>
    <joint name="R10_11" type="continuous">
        <origin xyz="0. 0.0 0." rpy="0 0 0"/>
        <axis xyz="0 1 0"/>
        <parent link="R10_FIX"/>
        <child link="R11"/>
    </joint>
    <link name="R11">
        <inertial>
            <mass value="0.0003"/>
            <origin xyz="0. 0. -8.600E-03" rpy="0. 0. 0."/>
            <inertia ixx="7.471E-09" ixy="0.0" ixz="0.0" iyy="7.471E-09" iyz="0.0" izz="1.500E-10"/>
        </inertial>
        <visual>
            <material name="WAMGrey">
                <color rgba="0.7 0.7 0.7 1.0"/>
            </material>
            <origin xyz="0.0 0.0 -8.600E-03"/>
            <geometry>
                <cylinder radius="0.001" length="0.0172"/>
            </geometry>
        </visual>
        <collision>
            <origin xyz="0.0 0.0 -8.600E-03"/>
            <geometry>
                <cylinder radius="0.001" length="0.0172"/>
            </geometry>
        </collision>
    </link>
    <joint name="R11_12_FIX" type="continuous">
        <origin xyz="0. 0.0 -8.600E-03" rpy="0 0 0"/>
        <axis xyz="1 0 0"/>
        <parent link="R11"/>
        <child link="R11_FIX"/>
    </joint>
    <link name="R11_FIX"/>
    <joint name="R11_12" type="continuous">
        <origin xyz="0. 0.0 0." rpy="0 0 0"/>
        <axis xyz="0 1 0"/>
        <parent link="R11_FIX"/>
        <child link="R12"/>
    </joint>
    <link name="R12">
        <inertial>
            <mass value="0.0003"/>
            <origin xyz="0. 0. -8.600E-03" rpy="0. 0. 0."/>
            <inertia ixx="7.471E-09" ixy="0.0" ixz="0.0" iyy="7.471E-09" iyz="0.0" izz="1.500E-10"/>
        </inertial>
        <visual>
            <material name="WAMGrey">
                <color rgba="0.7 0.7 0.7 1.0"/>
            </material>
            <origin xyz="0.0 0.0 -8.600E-03"/>
            <geometry>
                <cylinder radius="0.001" length="0.0172"/>
            </geometry>
        </visual>
        <collision>
            <origin xyz="0.0 0.0 -8.600E-03"/>
            <geometry>
                <cylinder radius="0.001" length="0.0172"/>
            </geometry>
        </collision>
    </link>
    <joint name="R12_13_FIX" type="continuous">
        <origin xyz="0. 0.0 -8.600E-03" rpy="0 0 0"/>
        <axis xyz="1 0 0"/>
        <parent link="R12"/>
        <child link="R12_FIX"/>
    </joint>
    <link name="R12_FIX"/>
    <joint name="R12_13" type="continuous">
        <origin xyz="0. 0.0 0." rpy="0 0 0"/>
        <axis xyz="0 1 0"/>
        <parent link="R12_FIX"/>
        <child link="R13"/>
    </joint>
    <link name="R13">
        <inertial>
            <mass value="0.0003"/>
            <origin xyz="0. 0. -8.600E-03" rpy="0. 0. 0."/>
            <inertia ixx="7.471E-09" ixy="0.0" ixz="0.0" iyy="7.471E-09" iyz="0.0" izz="1.500E-10"/>
        </inertial>
        <visual>
            <material name="WAMGrey">
                <color rgba="0.7 0.7 0.7 1.0"/>
            </material>
            <origin xyz="0.0 0.0 -8.600E-03"/>
            <geometry>
                <cylinder radius="0.001" length="0.0172"/>
            </geometry>
        </visual>
        <collision>
            <origin xyz="0.0 0.0 -8.600E-03"/>
            <geometry>
                <cylinder radius="0.001" length="0.0172"/>
            </geometry>
        </collision>
    </link>
    <joint name="R13_14_FIX" type="continuous">
        <origin xyz="0. 0.0 -8.600E-03" rpy="0 0 0"/>
        <axis xyz="1 0 0"/>
        <parent link="R13"/>
        <child link="R13_FIX"/>
    </joint>
    <link name="R13_FIX"/>
    <joint name="R13_14" type="continuous">
        <origin xyz="0. 0.0 0." rpy="0 0 0"/>
        <axis xyz="0 1 0"/>
        <parent link="R13_FIX"/>
        <child link="R14"/>
    </joint>
    <link name="R14">
        <inertial>
            <mass value="0.0003"/>
            <origin xyz="0. 0. -8.600E-03" rpy="0. 0. 0."/>
            <inertia ixx="7.471E-09" ixy="0.0" ixz="0.0" iyy="7.471E-09" iyz="0.0" izz="1.500E-10"/>
        </inertial>
        <visual>
            <material name="WAMGrey">
                <color rgba="0.7 0.7 0.7 1.0"/>
            </material>
            <origin xyz="0.0 0.0 -8.600E-03"/>
            <geometry>
                <cylinder radius="0.001" length="0.0172"/>
            </geometry>
        </visual>
        <collision>
            <origin xyz="0.0 0.0 -8.600E-03"/>
            <geometry>
                <cylinder radius="0.001" length="0.0172"/>
            </geometry>
        </collision>
    </link>
    <joint name="R14_15_FIX" type="continuous">
        <origin xyz="0. 0.0 -8.600E-03" rpy="0 0 0"/>
        <axis xyz="1 0 0"/>
        <parent link="R14"/>
        <child link="R14_FIX"/>
    </joint>
    <link name="R14_FIX"/>
    <joint name="R14_15" type="continuous">
        <origin xyz="0. 0.0 0." rpy="0 0 0"/>
        <axis xyz="0 1 0"/>
        <parent link="R14_FIX"/>
        <child link="R15"/>
    </joint>
    <link name="R15">
        <inertial>
            <mass value="0.0003"/>
            <origin xyz="0. 0. -8.600E-03" rpy="0. 0. 0."/>
            <inertia ixx="7.471E-09" ixy="0.0" ixz="0.0" iyy="7.471E-09" iyz="0.0" izz="1.500E-10"/>
        </inertial>
        <visual>
            <material name="WAMGrey">
                <color rgba="0.7 0.7 0.7 1.0"/>
            </material>
            <origin xyz="0.0 0.0 -8.600E-03"/>
            <geometry>
                <cylinder radius="0.001" length="0.0172"/>
            </geometry>
        </visual>
        <collision>
            <origin xyz="0.0 0.0 -8.600E-03"/>
            <geometry>
                <cylinder radius="0.001" length="0.0172"/>
            </geometry>
        </collision>
    </link>
    <joint name="R15_16_FIX" type="continuous">
        <origin xyz="0. 0.0 -8.600E-03" rpy="0 0 0"/>
        <axis xyz="1 0 0"/>
        <parent link="R15"/>
        <child link="R15_FIX"/>
    </joint>
    <link name="R15_FIX"/>
    <joint name="R15_16" type="continuous">
        <origin xyz="0. 0.0 0." rpy="0 0 0"/>
        <axis xyz="0 1 0"/>
        <parent link="R15_FIX"/>
        <child link="R16"/>
    </joint>
    <link name="R16">
        <inertial>
            <mass value="0.0003"/>
            <origin xyz="0. 0. -8.600E-03" rpy="0. 0. 0."/>
            <inertia ixx="7.471E-09" ixy="0.0" ixz="0.0" iyy="7.471E-09" iyz="0.0" izz="1.500E-10"/>
        </inertial>
        <visual>
            <material name="WAMGrey">
                <color rgba="0.7 0.7 0.7 1.0"/>
            </material>
            <origin xyz="0.0 0.0 -8.600E-03"/>
            <geometry>
                <cylinder radius="0.001" length="0.0172"/>
            </geometry>
        </visual>
        <collision>
            <origin xyz="0.0 0.0 -8.600E-03"/>
            <geometry>
                <cylinder radius="0.001" length="0.0172"/>
            </geometry>
        </collision>
    </link>
    <joint name="R16_17_FIX" type="continuous">
        <origin xyz="0. 0.0 -8.600E-03" rpy="0 0 0"/>
        <axis xyz="1 0 0"/>
        <parent link="R16"/>
        <child link="R16_FIX"/>
    </joint>
    <link name="R16_FIX"/>
    <joint name="R16_17" type="continuous">
        <origin xyz="0. 0.0 0." rpy="0 0 0"/>
        <axis xyz="0 1 0"/>
        <parent link="R16_FIX"/>
        <child link="R17"/>
    </joint>
    <link name="R17">
        <inertial>
            <mass value="0.0003"/>
            <origin xyz="0. 0. -8.600E-03" rpy="0. 0. 0."/>
            <inertia ixx="7.471E-09" ixy="0.0" ixz="0.0" iyy="7.471E-09" iyz="0.0" izz="1.500E-10"/>
        </inertial>
        <visual>
            <material name="WAMGrey">
                <color rgba="0.7 0.7 0.7 1.0"/>
            </material>
            <origin xyz="0.0 0.0 -8.600E-03"/>
            <geometry>
                <cylinder radius="0.001" length="0.0172"/>
            </geometry>
        </visual>
        <collision>
            <origin xyz="0.0 0.0 -8.600E-03"/>
            <geometry>
                <cylinder radius="0.001" length="0.0172"/>
            </geometry>
        </collision>
    </link>
    <joint name="R17_18_FIX" type="continuous">
        <origin xyz="0. 0.0 -8.600E-03" rpy="0 0 0"/>
        <axis xyz="1 0 0"/>
        <parent link="R17"/>
        <child link="R17_FIX"/>
    </joint>
    <link name="R17_FIX"/>
    <joint name="R17_18" type="continuous">
        <origin xyz="0. 0.0 0." rpy="0 0 0"/>
        <axis xyz="0 1 0"/>
        <parent link="R17_FIX"/>
        <child link="R18"/>
    </joint>
    <link name="R18">
        <inertial>
            <mass value="0.0003"/>
            <origin xyz="0. 0. -8.600E-03" rpy="0. 0. 0."/>
            <inertia ixx="7.471E-09" ixy="0.0" ixz="0.0" iyy="7.471E-09" iyz="0.0" izz="1.500E-10"/>
        </inertial>
        <visual>
            <material name="WAMGrey">
                <color rgba="0.7 0.7 0.7 1.0"/>
            </material>
            <origin xyz="0.0 0.0 -8.600E-03"/>
            <geometry>
                <cylinder radius="0.001" length="0.0172"/>
            </geometry>
        </visual>
        <collision>
            <origin xyz="0.0 0.0 -8.600E-03"/>
            <geometry>
                <cylinder radius="0.001" length="0.0172"/>
            </geometry>
        </collision>
    </link>
    <joint name="R18_19_FIX" type="continuous">
        <origin xyz="0. 0.0 -8.600E-03" rpy="0 0 0"/>
        <axis xyz="1 0 0"/>
        <parent link="R18"/>
        <child link="R18_FIX"/>
    </joint>
    <link name="R18_FIX"/>
    <joint name="R18_19" type="continuous">
        <origin xyz="0. 0.0 0." rpy="0 0 0"/>
        <axis xyz="0 1 0"/>
        <parent link="R18_FIX"/>
        <child link="R19"/>
    </joint>
    <link name="R19">
        <inertial>
            <mass value="0.0003"/>
            <origin xyz="0. 0. -8.600E-03" rpy="0. 0. 0."/>
            <inertia ixx="7.471E-09" ixy="0.0" ixz="0.0" iyy="7.471E-09" iyz="0.0" izz="1.500E-10"/>
        </inertial>
        <visual>
            <material name="WAMGrey">
                <color rgba="0.7 0.7 0.7 1.0"/>
            </material>
            <origin xyz="0.0 0.0 -8.600E-03"/>
            <geometry>
                <cylinder radius="0.001" length="0.0172"/>
            </geometry>
        </visual>
        <collision>
            <origin xyz="0.0 0.0 -8.600E-03"/>
            <geometry>
                <cylinder radius="0.001" length="0.0172"/>
            </geometry>
        </collision>
    </link>
    <joint name="R19_20_FIX" type="continuous">
        <origin xyz="0. 0.0 -8.600E-03" rpy="0 0 0"/>
        <axis xyz="1 0 0"/>
        <parent link="R19"/>
        <child link="R19_FIX"/>
    </joint>
    <link name="R19_FIX"/>
    <joint name="R19_20" type="continuous">
        <origin xyz="0. 0.0 0." rpy="0 0 0"/>
        <axis xyz="0 1 0"/>
        <parent link="R19_FIX"/>
        <child link="R20"/>
    </joint>
    <link name="R20">
        <inertial>
            <mass value="0.0003"/>
            <origin xyz="0. 0. -8.600E-03" rpy="0. 0. 0."/>
            <inertia ixx="7.471E-09" ixy="0.0" ixz="0.0" iyy="7.471E-09" iyz="0.0" izz="1.500E-10"/>
        </inertial>
        <visual>
            <material name="WAMGrey">
                <color rgba="0.7 0.7 0.7 1.0"/>
            </material>
            <origin xyz="0.0 0.0 -8.600E-03"/>
            <geometry>
                <cylinder radius="0.001" length="0.0172"/>
            </geometry>
        </visual>
        <collision>
            <origin xyz="0.0 0.0 -8.600E-03"/>
            <geometry>
                <cylinder radius="0.001" length="0.0172"/>
            </geometry>
        </collision>
    </link>
    <joint name="R20_21_FIX" type="continuous">
        <origin xyz="0. 0.0 -8.600E-03" rpy="0 0 0"/>
        <axis xyz="1 0 0"/>
        <parent link="R20"/>
        <child link="R20_FIX"/>
    </joint>
    <link name="R20_FIX"/>
    <joint name="R20_21" type="continuous">
        <origin xyz="0. 0.0 0." rpy="0 0 0"/>
        <axis xyz="0 1 0"/>
        <parent link="R20_FIX"/>
        <child link="R21"/>
    </joint>
    <link name="R21">
        <inertial>
            <mass value="0.0003"/>
            <origin xyz="0. 0. -8.600E-03" rpy="0. 0. 0."/>
            <inertia ixx="7.471E-09" ixy="0.0" ixz="0.0" iyy="7.471E-09" iyz="0.0" izz="1.500E-10"/>
        </inertial>
        <visual>
            <material name="WAMGrey">
                <color rgba="0.7 0.7 0.7 1.0"/>
            </material>
            <origin xyz="0.0 0.0 -8.600E-03"/>
            <geometry>
                <cylinder radius="0.001" length="0.0172"/>
            </geometry>
        </visual>
        <collision>
            <origin xyz="0.0 0.0 -8.600E-03"/>
            <geometry>
                <cylinder radius="0.001" length="0.0172"/>
            </geometry>
        </collision>
    </link>
    <joint name="R21_22_FIX" type="continuous">
        <origin xyz="0. 0.0 -8.600E-03" rpy="0 0 0"/>
        <axis xyz="1 0 0"/>
        <parent link="R21"/>
        <child link="R21_FIX"/>
    </joint>
    <link name="R21_FIX"/>
    <joint name="R21_22" type="continuous">
        <origin xyz="0. 0.0 0." rpy="0 0 0"/>
        <axis xyz="0 1 0"/>
        <parent link="R21_FIX"/>
        <child link="R22"/>
    </joint>
    <link name="R22">
        <inertial>
            <mass value="0.0003"/>
            <origin xyz="0. 0. -8.600E-03" rpy="0. 0. 0."/>
            <inertia ixx="7.471E-09" ixy="0.0" ixz="0.0" iyy="7.471E-09" iyz="0.0" izz="1.500E-10"/>
        </inertial>
        <visual>
            <material name="WAMGrey">
                <color rgba="0.7 0.7 0.7 1.0"/>
            </material>
            <origin xyz="0.0 0.0 -8.600E-03"/>
            <geometry>
                <cylinder radius="0.001" length="0.0172"/>
            </geometry>
        </visual>
        <collision>
            <origin xyz="0.0 0.0 -8.600E-03"/>
            <geometry>
                <cylinder radius="0.001" length="0.0172"/>
            </geometry>
        </collision>
    </link>
    <joint name="R22_23_FIX" type="continuous">
        <origin xyz="0. 0.0 -8.600E-03" rpy="0 0 0"/>
        <axis xyz="1 0 0"/>
        <parent link="R22"/>
        <child link="R22_FIX"/>
    </joint>
    <link name="R22_FIX"/>
    <joint name="R22_23" type="continuous">
        <origin xyz="0. 0.0 0." rpy="0 0 0"/>
        <axis xyz="0 1 0"/>
        <parent link="R22_FIX"/>
        <child link="R23"/>
    </joint>
    <link name="R23">
        <inertial>
            <mass value="0.0003"/>
            <origin xyz="0. 0. -8.600E-03" rpy="0. 0. 0."/>
            <inertia ixx="7.471E-09" ixy="0.0" ixz="0.0" iyy="7.471E-09" iyz="0.0" izz="1.500E-10"/>
        </inertial>
        <visual>
            <material name="WAMGrey">
                <color rgba="0.7 0.7 0.7 1.0"/>
            </material>
            <origin xyz="0.0 0.0 -8.600E-03"/>
            <geometry>
                <cylinder radius="0.001" length="0.0172"/>
            </geometry>
        </visual>
        <collision>
            <origin xyz="0.0 0.0 -8.600E-03"/>
            <geometry>
                <cylinder radius="0.001" length="0.0172"/>
            </geometry>
        </collision>
    </link>
    <joint name="R23_24_FIX" type="continuous">
        <origin xyz="0. 0.0 -8.600E-03" rpy="0 0 0"/>
        <axis xyz="1 0 0"/>
        <parent link="R23"/>
        <child link="R23_FIX"/>
    </joint>
    <link name="R23_FIX"/>
    <joint name="R23_24" type="continuous">
        <origin xyz="0. 0.0 0." rpy="0 0 0"/>
        <axis xyz="0 1 0"/>
        <parent link="R23_FIX"/>
        <child link="R24"/>
    </joint>
    <link name="R24">
        <inertial>
            <mass value="0.0003"/>
            <origin xyz="0. 0. -8.600E-03" rpy="0. 0. 0."/>
            <inertia ixx="7.471E-09" ixy="0.0" ixz="0.0" iyy="7.471E-09" iyz="0.0" izz="1.500E-10"/>
        </inertial>
        <visual>
            <material name="WAMGrey">
                <color rgba="0.7 0.7 0.7 1.0"/>
            </material>
            <origin xyz="0.0 0.0 -8.600E-03"/>
            <geometry>
                <cylinder radius="0.001" length="0.0172"/>
            </geometry>
        </visual>
        <collision>
            <origin xyz="0.0 0.0 -8.600E-03"/>
            <geometry>
                <cylinder radius="0.001" length="0.0172"/>
            </geometry>
        </collision>
    </link>
    <joint name="R24_25_FIX" type="continuous">
        <origin xyz="0. 0.0 -8.600E-03" rpy="0 0 0"/>
        <axis xyz="1 0 0"/>
        <parent link="R24"/>
        <child link="R24_FIX"/>
    </joint>
    <link name="R24_FIX"/>
    <joint name="R24_25" type="continuous">
        <origin xyz="0. 0.0 0." rpy="0 0 0"/>
        <axis xyz="0 1 0"/>
        <parent link="R24_FIX"/>
        <child link="R25"/>
    </joint>
    <link name="R25">
        <inertial>
            <mass value="0.0003"/>
            <origin xyz="0. 0. -8.600E-03" rpy="0. 0. 0."/>
            <inertia ixx="7.471E-09" ixy="0.0" ixz="0.0" iyy="7.471E-09" iyz="0.0" izz="1.500E-10"/>
        </inertial>
        <visual>
            <material name="WAMGrey">
                <color rgba="0.7 0.7 0.7 1.0"/>
            </material>
            <origin xyz="0.0 0.0 -8.600E-03"/>
            <geometry>
                <cylinder radius="0.001" length="0.0172"/>
            </geometry>
        </visual>
        <collision>
            <origin xyz="0.0 0.0 -8.600E-03"/>
            <geometry>
                <cylinder radius="0.001" length="0.0172"/>
            </geometry>
        </collision>
    </link>
    <joint name="R25_26_FIX" type="continuous">
        <origin xyz="0. 0.0 -8.600E-03" rpy="0 0 0"/>
        <axis xyz="1 0 0"/>
        <parent link="R25"/>
        <child link="R25_FIX"/>
    </joint>
    <link name="R25_FIX"/>
    <joint name="R25_26" type="continuous">
        <origin xyz="0. 0.0 0." rpy="0 0 0"/>
        <axis xyz="0 1 0"/>
        <parent link="R25_FIX"/>
        <child link="R26"/>
    </joint>
    <link name="R26">
        <inertial>
            <mass value="0.0003"/>
            <origin xyz="0. 0. -8.600E-03" rpy="0. 0. 0."/>
            <inertia ixx="7.471E-09" ixy="0.0" ixz="0.0" iyy="7.471E-09" iyz="0.0" izz="1.500E-10"/>
        </inertial>
        <visual>
            <material name="WAMGrey">
                <color rgba="0.7 0.7 0.7 1.0"/>
            </material>
            <origin xyz="0.0 0.0 -8.600E-03"/>
            <geometry>
                <cylinder radius="0.001" length="0.0172"/>
            </geometry>
        </visual>
        <collision>
            <origin xyz="0.0 0.0 -8.600E-03"/>
            <geometry>
                <cylinder radius="0.001" length="0.0172"/>
            </geometry>
        </collision>
    </link>
    <joint name="R26_27_FIX" type="continuous">
        <origin xyz="0. 0.0 -8.600E-03" rpy="0 0 0"/>
        <axis xyz="1 0 0"/>
        <parent link="R26"/>
        <child link="R26_FIX"/>
    </joint>
    <link name="R26_FIX"/>
    <joint name="R26_27" type="continuous">
        <origin xyz="0. 0.0 0." rpy="0 0 0"/>
        <axis xyz="0 1 0"/>
        <parent link="R26_FIX"/>
        <child link="R27"/>
    </joint>
    <link name="R27">
        <inertial>
            <mass value="0.0003"/>
            <origin xyz="0. 0. -8.600E-03" rpy="0. 0. 0."/>
            <inertia ixx="7.471E-09" ixy="0.0" ixz="0.0" iyy="7.471E-09" iyz="0.0" izz="1.500E-10"/>
        </inertial>
        <visual>
            <material name="WAMGrey">
                <color rgba="0.7 0.7 0.7 1.0"/>
            </material>
            <origin xyz="0.0 0.0 -8.600E-03"/>
            <geometry>
                <cylinder radius="0.001" length="0.0172"/>
            </geometry>
        </visual>
        <collision>
            <origin xyz="0.0 0.0 -8.600E-03"/>
            <geometry>
                <cylinder radius="0.001" length="0.0172"/>
            </geometry>
        </collision>
    </link>

    <joint name="ROPE_TO_BALL" type="fixed">
        <parent link="R27"/>
        <child link="ball"/>
        <origin xyz="0 0 -8.350E-03" rpy="0 0 0"/>
    </joint>

    <link name="ball">
        <inertial>
            <mass value="0.02"/>
            <inertia ixx="5.3E-06" ixy="0.0" ixz="0.0" iyy="5.3E-06" iyz="0.0" izz="5.3E-06"/>
        </inertial>
        <visual>
            <material name="red">
                <color rgba="1.0 0 0 1."/>
            </material>
            <geometry>
                <sphere radius="0.02"/>
            </geometry>
        </visual>
    </link>

</robot>
