<?xml version="1.0" ?>
<!-- =================================================================================== -->
<!-- |    This document was autogenerated by xacro from wam7.urdf.xacro                | -->
<!-- |    EDITING THIS FILE BY HAND IS NOT RECOMMENDED                                 | -->
<!-- =================================================================================== -->
<robot name="wam" xmlns:xacro="http://www.ros.org/wiki/xacro">

    <!-- Materials -->
    <material name="WAMGrey">
        <color rgba="0.7 0.7 0.7 1.0"/>
    </material>

    <!-- Root link is in the world frame-->
    <link name="world"/>
    <joint name="wam_fixed_joint" type="fixed">
        <parent link="world"/>
        <child link="base_link"/>
        <origin rpy="0 0 1.5707" xyz="0.0 0.0 0.0"/>
    </joint>

    <link name="base_link">
        <inertial>
            <origin rpy="1.57 0 0" xyz="0.0 0.0 0.84"/>
            <mass value="1"/>
            <inertia ixx="0.1" ixy="0" ixz="0" iyy="0.1" iyz="0" izz="0.1"/>
        </inertial>
        <visual>
            <material name="WAMGrey">
                <color rgba="0.7 0.7 0.7 0.0"/>
            </material>
            <geometry>
                <mesh filename="sw_meshes/base_link_fine.obj"/>
            </geometry>
        </visual>
        <collision>
            <geometry>
                <mesh filename="sw_meshes/base_link_convex.obj"/>
            </geometry>
        </collision>
    </link>
    <joint name="R_SFE" type="revolute">
        <parent link="base_link"/>
        <child link="shoulder_yaw_link"/>
        <origin rpy="0 0 -1.57079632679" xyz="0 0 0.346"/>
        <axis xyz="0 0 1"/>
        <limit effort="60" lower="-2.6" upper="2.6" velocity="2.0"/>
        <dynamics damping="0.9" friction="0"/>
    </joint>

    <link name="shoulder_yaw_link">
        <inertial>
            <origin xyz="-.00443422 -.00066489 -0.1289039 "/>
            <mass value="5.0"/>
            <inertia ixx=".13488033" ixy="-0.00012485" ixz="0.00213041" iyy=".09046330" iyz="-.00068555"
                     izz=".11328369"/>
        </inertial>
        <visual>
            <material name="WAMGrey">
                <color rgba="0.7 0.7 0.7 1.0"/>
            </material>
            <geometry>
                <mesh filename="sw_meshes/shoulder_link_fine.obj"/>
            </geometry>
        </visual>
        <collision>
            <geometry>
                <mesh filename="sw_meshes/shoulder_link_convex_decomposition.obj"/>
            </geometry>
        </collision>
    </link>

    <joint name="R_SAA" type="revolute">
        <parent link="shoulder_yaw_link"/>
        <child link="shoulder_pitch_link"/>
        <origin rpy="-1.57079632679 0 0" xyz="0 0 0"/>
        <axis xyz="0 0 1"/>
        <limit effort="60" lower="-2.1" upper="2.0" velocity="2.0"/>
        <dynamics damping="0.25" friction="0"/>
    </joint>

    <link name="shoulder_pitch_link">
        <visual>
            <material name="WAMGrey">
                <color rgba="0.7 0.7 0.7 1.0"/>
            </material>
            <geometry>
                <mesh filename="sw_meshes/shoulder_pitch_link_fine.obj"/>
            </geometry>
        </visual>
        <inertial>
            <origin xyz="-.00236981 -.01542114 .03105614 "/>
            <mass value="3.87493756"/>
            <inertia ixx="0.02140958" ixy="-0.00002461" ixz="0.00027172" iyy="0.015589060" iyz="0.0018192"
                     izz="0.01377875"/>
        </inertial>
        <collision>
            <geometry>
                <mesh filename="sw_meshes/shoulder_pitch_link_convex.obj"/>
            </geometry>
        </collision>
    </link>

    <joint name="R_HR" type="revolute">
        <parent link="shoulder_pitch_link"/>
        <child link="upper_arm_link"/>
        <origin rpy="1.57079632679 0 0" xyz="0 0 0"/>
        <axis xyz="0 0 1"/>
        <limit effort="45" lower="-2.8" upper="2.8" velocity="2.0"/>
        <dynamics damping="0.75" friction="0"/>
    </joint>

    <link name="upper_arm_link">
        <inertial>
            <origin xyz="0.00683258580000000 0.000033090000000 0.392492300000000"/>
            <mass value="2.20228141"/>
            <inertia ixx=".05911077" ixy="-0.00000738" ixz="-0.00249612" iyy="0.05927043" iyz="0.00001767"
                     izz="0.0032455"/>
        </inertial>
        <visual>
            <material name="WAMGrey">
                <color rgba="0.7 0.7 0.7 1.0"/>
            </material>
            <geometry>
                <mesh filename="sw_meshes/upper_arm_link_fine.obj"/>
            </geometry>
        </visual>
        <collision>
            <geometry>
                <mesh filename="sw_meshes/upper_arm_link_convex_decomposition.obj"/>
            </geometry>
        </collision>
    </link>

    <joint name="R_EB" type="revolute">
        <parent link="upper_arm_link"/>
        <child link="forearm_link"/>
        <origin rpy="-1.57079632679 0 0" xyz="0.045 0 0.55"/>
        <axis xyz="0 0 1"/>
        <limit effort="30" lower="-0.9" upper="3.2" velocity="2.00"/>
        <dynamics damping="0.4" friction="0"/>
    </joint>

    <link name="forearm_link">
        <inertial>
            <mass value="1.06513649"/>
            <origin rpy="1.5707 0 0" xyz="0.01095471 0.14053900 -0.00002567"/>
            <inertia ixx="0.03952350" ixy="0.00000189" ixz="0.00003117" iyy="0.04008214" iyz="0.00000131"
                     izz="0.00210299"/>
        </inertial>
        <visual>
            <origin rpy="0 0 0" xyz="0 0 0"/>
            <geometry name="link_j4_visual">
                <mesh filename="sw_meshes/wam4.obj"/>
            </geometry>
        </visual>
        <collision>
            <origin rpy="1.5707 0 0" xyz="0 0 0"/>
            <geometry name="link_j4_collision">
                <mesh filename="sw_meshes/wam4.obj"/>
            </geometry>
            <contact_coefficients kd="1000.0" kp="1000.0" mu="0"/>
        </collision>
    </link>

    <joint name="FOREARM_TO_CUP" type="fixed">
        <parent link="forearm_link"/>
        <child link="cup"/>
        <origin xyz="-0.1 -0.3225 0.0"/>
    </joint>

    <link name="cup">
        <inertial>
            <mass value="0.132"/>
            <origin xyz="-3.75236e-10 8.27811e-05 0.0947015" rpy="0.0 -0.0199993 0.0"/>
            <inertia ixx="0.000285643" ixy="0.0" ixz="0.0" iyy="0.000270485" iyz="0.0" izz="9.65696e-05"/>
        </inertial>
        <visual>
            <origin rpy="1.5707 -1.5707 0" xyz="0. 0. 0."/>
            <material name="WAMGrey">
                <color rgba="0.7 0.7 0.7 1.0"/>
            </material>
            <geometry name="cup_visual">
                <mesh filename="sw_meshes/cup.obj" scale="0.001 0.001 0.001"/>
            </geometry>
        </visual>
        <collision>
            <origin rpy="1.5707 -1.5707 0" xyz="0 0 0"/>
            <geometry name="cup_collision">
                <mesh filename="sw_meshes/cup.obj" scale="0.001 0.001 0.001"/>
            </geometry>
        </collision>
    </link>

    <!--  <joint name="attach" type="fixed">-->
    <!--    <origin xyz="0.0 0.0 0.0" rpy="0 0 0"/>-->
    <!--    <parent link="cup"/>-->
    <!--    <child link="soft"/>-->
    <!--  </joint>-->

    <!--  <link name="soft">-->
    <!--    <fem>-->
    <!--      <origin rpy="0.0 0.0 0.0" xyz="0 0 -1.2"/>-->
    <!--      <density value="1000"/>-->
    <!--      <youngs value="1e5"/>-->
    <!--      <poissons value="0.45"/>-->
    <!--      <damping value="0.0"/>-->
    <!--      <attachDistance value="0.0"/>-->
    <!--      <tetmesh filename="icosphere_mod.tet"/>-->
    <!--    </fem>-->
    <!--  </link>-->


</robot>
